<?xml version="1.0" ?>
<!-- =================================================================================== -->
<!-- |    This document was autogenerated by xacro from rb10_moveit.xacro              | -->
<!-- |    EDITING THIS FILE BY HAND IS NOT RECOMMENDED                                 | -->
<!-- =================================================================================== -->
<!-- Cobot Robot -->
<robot name="rb10">
  <material name="grey">
    <color rgba="0.2 0.2 0.2 1.0"/>
  </material>
  <!--======================= Links =========================-->
  <!-- Base Footprint -->
  <link name="base_footprint">
    <visual>
      <origin rpy="0 0 0" xyz="0 0 0"/>
      <geometry>
        <box size="0.001 0.001 0.001"/>
      </geometry>
      <material name="grey"/>
    </visual>
  </link>
  <!-- 0 -->
  <link name="Axis_0">
    <visual>
      <origin rpy="0 0 0" xyz="0 0 0"/>
      <geometry>
        <mesh filename="package://rb_description/meshes/visual/RB10/RB10-AXIS-0.stl" scale="0.001 0.001 0.001"/>
      </geometry>
      <material name="grey"/>
    </visual>
    <collision>
      <origin rpy="0 0 0" xyz="0 0 0"/>
      <geometry>
        <mesh filename="package://rb_description/meshes/collision/RB10/RB10-AXIS-0.stl" scale="0.001 0.001 0.001"/>
      </geometry>
    </collision>
  </link>
  <!-- Base -->
  <link name="Axis_1">
    <visual>
      <origin rpy="0 0 0" xyz="0 0 0"/>
      <geometry>
        <mesh filename="package://rb_description/meshes/visual/RB10/RB10-AXIS-1.stl" scale="0.001 0.001 0.001"/>
      </geometry>
      <material name="grey"/>
    </visual>
    <collision>
      <origin rpy="0 0 0" xyz="0 0 0"/>
      <geometry>
        <mesh filename="package://rb_description/meshes/collision/RB10/RB10-AXIS-1.stl" scale="0.001 0.001 0.001"/>
      </geometry>
    </collision>
  </link>
  <!-- Shoulder -->
  <link name="Axis_2">
    <visual>
      <origin rpy="0 0 0" xyz="0 0 -0.197"/>
      <geometry>
        <mesh filename="package://rb_description/meshes/visual/RB10/RB10-AXIS-2.stl" scale="0.001 0.001 0.001"/>
      </geometry>
      <material name="grey"/>
    </visual>
    <collision>
      <origin rpy="0 0 0" xyz="0 0 -0.197"/>
      <geometry>
        <mesh filename="package://rb_description/meshes/collision/RB10/RB10-AXIS-2.stl" scale="0.001 0.001 0.001"/>
      </geometry>
    </collision>
  </link>
  <!-- Elbow -->
  <link name="Axis_3">
    <visual>
      <origin rpy="0 0 0" xyz="0 0 -0.8097000000000001 "/>
      <geometry>
        <mesh filename="package://rb_description/meshes/visual/RB10/RB10-AXIS-3.stl" scale="0.001 0.001 0.001"/>
      </geometry>
      <material name="grey"/>
    </visual>
    <collision>
      <origin rpy="0 0 0" xyz="0 0 -0.8097000000000001"/>
      <geometry>
        <mesh filename="package://rb_description/meshes/collision/RB10/RB10-AXIS-3.stl" scale="0.001 0.001 0.001"/>
      </geometry>
    </collision>
  </link>
  <!-- Wrist1 -->
  <link name="Axis_4">
    <visual>
      <origin rpy="0 0 0" xyz="0 0 -1.3798500000000002"/>
      <geometry>
        <mesh filename="package://rb_description/meshes/visual/RB10/RB10-AXIS-4.stl" scale="0.001 0.001 0.001"/>
      </geometry>
      <material name="grey"/>
    </visual>
    <collision>
      <origin rpy="0 0 0" xyz="0 0 -1.3798500000000002"/>
      <geometry>
        <mesh filename="package://rb_description/meshes/collision/RB10/RB10-AXIS-4.stl" scale="0.001 0.001 0.001"/>
      </geometry>
    </collision>
  </link>
  <!-- Wrist2 -->
  <link name="Axis_5">
    <visual>
      <origin rpy="0 0 0" xyz="0 0.15625  -1.3798500000000002"/>
      <geometry>
        <mesh filename="package://rb_description/meshes/visual/RB10/RB10-AXIS-5.stl" scale="0.001 0.001 0.001"/>
      </geometry>
      <material name="grey"/>
    </visual>
    <collision>
      <origin rpy="0 0 0" xyz="0 0.15625  -1.3798500000000002"/>
      <geometry>
        <mesh filename="package://rb_description/meshes/collision/RB10/RB10-AXIS-5.stl" scale="0.001 0.001 0.001"/>
      </geometry>
    </collision>
  </link>
  <!-- Wrist3 -->
  <link name="Axis_6">
    <visual>
      <origin rpy="0 0 0" xyz="0 0.15625 -1.4970000000000003"/>
      <geometry>
        <mesh filename="package://rb_description/meshes/visual/RB10/RB10-AXIS-6.stl" scale="0.001 0.001 0.001"/>
      </geometry>
      <material name="grey"/>
    </visual>
    <collision>
      <origin rpy="0 0 0" xyz="0 0.15625 -1.4970000000000003"/>
      <geometry>
        <mesh filename="package://rb_description/meshes/collision/RB10/RB10-AXIS-6.stl" scale="0.001 0.001 0.001"/>
      </geometry>
    </collision>
  </link>
  <!-- TCP -->
  <link name="Tool_Center_Point">
    <visual>
      <origin rpy="0 0 0" xyz="0.11715 0 -1.4970000000000003"/>
      <geometry>
        <box size="0.001 0.001 0.001"/>
      </geometry>
      <material name="grey"/>
    </visual>
  </link>
  <!-- Joint -->
  <joint name="ground" type="fixed">
    <parent link="base_footprint"/>
    <child link="Axis_0"/>
    <origin rpy="0 0 0" xyz="0 0 0"/>
    <axis xyz="0 0 1"/>
  </joint>
  <joint name="base" type="continuous">
    <parent link="Axis_0"/>
    <child link="Axis_1"/>
    <origin rpy="0 0 0" xyz="0 0 0"/>
    <axis xyz="0 0 1"/>
  </joint>
  <joint name="shoulder" type="continuous">
    <parent link="Axis_1"/>
    <child link="Axis_2"/>
    <origin rpy="0 0 0" xyz="0 0 0.197 "/>
    <axis xyz="0 1 0"/>
  </joint>
  <joint name="elbow" type="continuous">
    <parent link="Axis_2"/>
    <child link="Axis_3"/>
    <origin rpy="0 0 0" xyz="0 0 0.6127"/>
    <axis xyz="0 1 0"/>
  </joint>
  <joint name="wrist1" type="continuous">
    <parent link="Axis_3"/>
    <child link="Axis_4"/>
    <origin rpy="0 0 0" xyz="0 0 0.57015"/>
    <axis xyz="0 1 0"/>
  </joint>
  <joint name="wrist2" type="continuous">
    <parent link="Axis_4"/>
    <child link="Axis_5"/>
    <origin rpy="0 0 0" xyz="0 -0.15625 0 "/>
    <axis xyz="0 0 1"/>
  </joint>
  <joint name="wrist3" type="continuous">
    <parent link="Axis_5"/>
    <child link="Axis_6"/>
    <origin rpy="0 0 0" xyz="0 0 0.11715"/>
    <!-- ${base_offset - elbow_offset + wrist2wrist} ${wrist2wrist} -->
    <axis xyz="0 1 0"/>
  </joint>
  <joint name="Tool_Flange" type="fixed">
    <parent link="Axis_6"/>
    <child link="Tool_Center_Point"/>
    <origin rpy="0 0 0" xyz="0 -0.1153 0"/>
    <axis xyz="0 0 0"/>
  </joint>
</robot>
